Workbook

Sheet Instructions & Testers
A1: MedinaCares Volunteer Service Awards — Tester Guide & Assignment
A3: How to test
A4: Thank you for testing MedinaCares! Please follow these steps:
A5: 1. Find your name in the Testers table below and note your assigned platform tab(s).
A6: 2. Open your tab (iOS, Android, Desktop Chrome, Desktop Firefox, or Desktop Other).
A7: 3. Cases are grouped by persona. Sign in with an account of that persona, then work top to bottom.
A8: 4. For each row read the User story, do the Steps, and compare to 'Expected behavior (what you should see)'.
A9: 5. In 'Result' pick Pass / Fail / Blocked / Not tested / N/A.
A10: Pass = worked as described. Fail = did not. Blocked = couldn't test (needed data/access). N/A = not applicable.
A11: 6. Put details in 'Comments' — for any Fail, what happened + how to reproduce.
A12: 7. For a Fail, screenshot it into the shared folder named <Test ID>-<your name>.png (e.g. SV14-aisha.png) and note it in Comments.
A13: 8. Put your name in 'Tester' for rows you complete, and update your Status below.
... A17: Questions: email mcc@medinaacademy.org.
A19: Tester name | B19: Device / OS | C19: Browser | D19: Assigned tab(s) | E19: Status
A20: Aisha Khan (example) | B20: iPhone 14, iOS 17 | C20: Safari | D20: iOS | E20: In progress

Sheet Summary
A1: Testing summary (live counts)
A2: Counts update automatically as testers fill in each platform tab's Result column.
A4: Overall by platform
A5: Platform | B5: Total | C5: Pass | D5: Fail | E5: Blocked | F5: Not tested | G5: Untested (blank) | H5: % complete
A6: iOS | B6: 97 | C6: =COUNTIF('iOS'!$E$3:$E$107,"Pass") | D6: =COUNTIF('iOS'!$E$3:$E$107,"Fail") | E6: =COUNTIF('iOS'!$E$3:$E$107,"Blocked") | F6: =COUNTIF('iOS'!$E$3:$E$107,"Not tested") | G6: =$B6-COUNTA('iOS'!$E$3:$E$107) | H6: =IF($B6=0,0,(COUNTIF('iOS'!$E$3:$E$107,"Pass")+COUNTIF('iOS'!$E$3:$E$107,"Fail")+COUNTIF('iOS'!$E$3:$E$107,"Blocked")+COUNTIF('iOS'!$E$3:$E$107,"Not tested"))/$B6)
A7: Android | B7: 97 | C7: =COUNTIF('Android'!$E$3:$E$107,"Pass") | D7: =COUNTIF('Android'!$E$3:$E$107,"Fail") | E7: =COUNTIF('Android'!$E$3:$E$107,"Blocked") | F7: =COUNTIF('Android'!$E$3:$E$107,"Not tested") | G7: =$B7-COUNTA('Android'!$E$3:$E$107) | H7: =IF($B7=0,0,(COUNTIF('Android'!$E$3:$E$107,"Pass")+COUNTIF('Android'!$E$3:$E$107,"Fail")+COUNTIF('Android'!$E$3:$E$107,"Blocked")+COUNTIF('Android'!$E$3:$E$107,"Not tested"))/$B7)
A8: Desktop Chrome | B8: 97 | C8: =COUNTIF('Desktop Chrome'!$E$3:$E$107,"Pass") | D8: =COUNTIF('Desktop Chrome'!$E$3:$E$107,"Fail") | E8: =COUNTIF('Desktop Chrome'!$E$3:$E$107,"Blocked") | F8: =COUNTIF('Desktop Chrome'!$E$3:$E$107,"Not tested") | G8: =$B8-COUNTA('Desktop Chrome'!$E$3:$E$107) | H8: =IF($B8=0,0,(COUNTIF('Desktop Chrome'!$E$3:$E$107,"Pass")+COUNTIF('Desktop Chrome'!$E$3:$E$107,"Fail")+COUNTIF('Desktop Chrome'!$E$3:$E$107,"Blocked")+COUNTIF('Desktop Chrome'!$E$3:$E$107,"Not tested"))/$B8)
A9: Desktop Firefox | B9: 97 | C9: =COUNTIF('Desktop Firefox'!$E$3:$E$107,"Pass") | D9: =COUNTIF('Desktop Firefox'!$E$3:$E$107,"Fail") | E9: =COUNTIF('Desktop Firefox'!$E$3:$E$107,"Blocked") | F9: =COUNTIF('Desktop Firefox'!$E$3:$E$107,"Not tested") | G9: =$B9-COUNTA('Desktop Firefox'!$E$3:$E$107) | H9: =IF($B9=0,0,(COUNTIF('Desktop Firefox'!$E$3:$E$107,"Pass")+COUNTIF('Desktop Firefox'!$E$3:$E$107,"Fail")+COUNTIF('Desktop Firefox'!$E$3:$E$107,"Blocked")+COUNTIF('Desktop Firefox'!$E$3:$E$107,"Not tested"))/$B9)
A10: Desktop Other | B10: 97 | C10: =COUNTIF('Desktop Other'!$E$3:$E$107,"Pass") | D10: =COUNTIF('Desktop Other'!$E$3:$E$107,"Fail") | E10: =COUNTIF('Desktop Other'!$E$3:$E$107,"Blocked") | F10: =COUNTIF('Desktop Other'!$E$3:$E$107,"Not tested") | G10: =$B10-COUNTA('Desktop Other'!$E$3:$E$107) | H10: =IF($B10=0,0,(COUNTIF('Desktop Other'!$E$3:$E$107,"Pass")+COUNTIF('Desktop Other'!$E$3:$E$107,"Fail")+COUNTIF('Desktop Other'!$E$3:$E$107,"Blocked")+COUNTIF('Desktop Other'!$E$3:$E$107,"Not tested"))/$B10)
A12: Pass count by persona × platform
A13: Persona group | B13: iOS | C13: Android | D13: Desktop Chrome | E13: Desktop Firefox | F13: Desktop Other | G13: Cases
A14: Account & access (all roles) | B14: =COUNTIF('iOS'!$E$4:$E$9,"Pass") | C14: =COUNTIF('Android'!$E$4:$E$9,"Pass") | D14: =COUNTIF('Desktop Chrome'!$E$4:$E$9,"Pass") | E14: =COUNTIF('Desktop Firefox'!$E$4:$E$9,"Pass") | F14: =COUNTIF('Desktop Other'!$E$4:$E$9,"Pass") | G14: 6
A15: Participant (grades 6–12) | B15: =COUNTIF('iOS'!$E$11:$E$34,"Pass") | C15: =COUNTIF('Android'!$E$11:$E$34,"Pass") | D15: =COUNTIF('Desktop Chrome'!$E$11:$E$34,"Pass") | E15: =COUNTIF('Desktop Firefox'!$E$11:$E$34,"Pass") | F15: =COUNTIF('Desktop Other'!$E$11:$E$34,"Pass") | G15: 24
A16: Parent — elementary (grades 2–5 child) | B16: =COUNTIF('iOS'!$E$36:$E$50,"Pass") | C16: =COUNTIF('Android'!$E$36:$E$50,"Pass") | D16: =COUNTIF('Desktop Chrome'!$E$36:$E$50,"Pass") | E16: =COUNTIF('Desktop Firefox'!$E$36:$E$50,"Pass") | F16: =COUNTIF('Desktop Other'!$E$36:$E$50,"Pass") | G16: 15
A17: Parent — viewer (grades 6–12 student) | B17: =COUNTIF('iOS'!$E$52:$E$56,"Pass") | C17: =COUNTIF('Android'!$E$52:$E$56,"Pass") | D17: =COUNTIF('Desktop Chrome'!$E$52:$E$56,"Pass") | E17: =COUNTIF('Desktop Firefox'!$E$52:$E$56,"Pass") | F17: =COUNTIF('Desktop Other'!$E$52:$E$56,"Pass") | G17: 5
A18: Supervisor (created by an Admin) | B18: =COUNTIF('iOS'!$E$58:$E$76,"Pass") | C18: =COUNTIF('Android'!$E$58:$E$76,"Pass") | D18: =COUNTIF('Desktop Chrome'!$E$58:$E$76,"Pass") | E18: =COUNTIF('Desktop Firefox'!$E$58:$E$76,"Pass") | F18: =COUNTIF('Desktop Other'!$E$58:$E$76,"Pass") | G18: 19
A19: Admin (org-scoped) | B19: =COUNTIF('iOS'!$E$78:$E$91,"Pass") | C19: =COUNTIF('Android'!$E$78:$E$91,"Pass") | D19: =COUNTIF('Desktop Chrome'!$E$78:$E$91,"Pass") | E19: =COUNTIF('Desktop Firefox'!$E$78:$E$91,"Pass") | F19: =COUNTIF('Desktop Other'!$E$78:$E$91,"Pass") | G19: 14
A20: Super Admin (global) | B20: =COUNTIF('iOS'!$E$93:$E$104,"Pass") | C20: =COUNTIF('Android'!$E$93:$E$104,"Pass") | D20: =COUNTIF('Desktop Chrome'!$E$93:$E$104,"Pass") | E20: =COUNTIF('Desktop Firefox'!$E$93:$E$104,"Pass") | F20: =COUNTIF('Desktop Other'!$E$93:$E$104,"Pass") | G20: 12
A21: Cross-cutting | B21: =COUNTIF('iOS'!$E$106:$E$107,"Pass") | C21: =COUNTIF('Android'!$E$106:$E$107,"Pass") | D21: =COUNTIF('Desktop Chrome'!$E$106:$E$107,"Pass") | E21: =COUNTIF('Desktop Firefox'!$E$106:$E$107,"Pass") | F21: =COUNTIF('Desktop Other'!$E$106:$E$107,"Pass") | G21: 2

Sheet iOS
A1: Test cases — iOS
A2: ID | B2: User story | C2: Steps to perform | D2: Expected behavior (what you should see) | E2: Result | F2: Comments | G2: Tester
A3: Account & access (all roles)
A4: AC1 | B4: As any user, I want to log in with email and password. | C4: Enter valid email/password and Sign in. | D4: You're signed in and taken to your role's home.
A5: AC2 | B5: As any user, I want to reveal my password while typing. | C5: Tap the eye icon in the password field. | D5: Password text toggles visible/hidden.
A6: AC3 | B6: As any user, I want to reset a forgotten password by email. | C6: Forgot password → enter email → open email → follow link → set new password → sign in. | D6: Reset email arrives; link works; new password signs in; old one fails.
A7: AC4 | B7: As any user, I want to sign out. | C7: Use Sign out. | D7: Logged out; returned to login/landing.
A8: AC5 | B8: As any user, I want a clear error for bad credentials. | C8: Enter a wrong password. | D8: Clear 'login failed' message; stay on login.
A9: AC6 | B9: As any user, my session persists and protected pages are guarded. | C9: Sign in, refresh; then sign out and open a protected URL directly. | D9: Refresh stays signed in; protected pages redirect to login when signed out.
A10: Participant (grades 6–12)
A11: PT1 | B11: As a student (6–12), I want to self-register with the form. | C11: Create account → student option; fill name, email, password, grade, school, parent email; submit. | D11: Account created; signed in on the participant dashboard.
A12: PT2 | B12: As a student, I want to enter an organization code during sign-up. | C12: Enter a code in the Organization code field (optional) and submit. | D12: A valid code enrolls me in that org; a bad code is rejected; blank is allowed.
A13: PT3 | B13: As a participant, I want the correct 7 left-menu tabs. | C13: Look at the left menu. | D13: Exactly: Dashboard, Sign Up, Submit My Hours, Leaderboard, My Reports, My Profile, Help.
A14: PT4 | B14: As a participant, I want a dashboard of my hours and next medal. | C14: Open the dashboard. | D14: Approved-hours ring, next medal + hours to go, and quick actions.
A15: PT5 | B15: As a participant, I want to find and sign up for an opportunity. | C15: Sign Up → Upcoming events → open one → Sign Up. | D15: Registered; confirmation; it moves to My sign-ups.
A16: PT6 | B16: As a participant, I want to add a signed-up event to my calendar. | C16: My sign-ups → add to calendar. | D16: An .ics downloads with correct title/date/time/location.
A17: PT7 | B17: As a participant, I want to see my past events. | C17: Sign Up → Past tab. | D17: Past events are listed.
A18: PT8 | B18: As a participant, I want to search opportunities. | C18: Use the search box (name/description/location). | D18: List filters to matches.
A19: PT9 | B19: As a participant, I want to withdraw from an event. | C19: My sign-ups → red Withdraw → confirm. | D19: Removed; can re-sign up later if space.
A20: PT10 | B20: As a participant, I can only join grade-appropriate events. | C20: Try an event outside your grade range. | D20: Not available / blocked with a grade message.
A21: PT11 | B21: As a participant, I only see my org's or open events. | C21: Browse opportunities. | D21: Open-to-all show; other orgs' private events don't appear.
A22: PT12 | B22: As a participant, I want to check in on event day. | C22: On the day, within the window, use the Check-In panel. | D22: Check-in succeeds; before the window shows 'Not open yet'.
... A34: PT24 | B34: As a participant, I want the recycling ribbon on every page. | C34: Navigate around signed in. | D34: Green ribbon with cans + 100,000 countdown on every page.
A35: Parent — elementary (grades 2–5 child)
A36: PE1 | B36: As a parent, I want to register to manage my grade 2–5 child. | C36: Create account → parent of a 2–5 child. | D36: Parent account created.
A37: PE2 | B37: As an elementary parent, I want the right menu tabs. | C37: Look at the left menu. | D37: Dashboard and Find Opportunities (Help in footer).
A38: PE3 | B38: As a parent, I want to add a managed child (2–5). | C38: Add child with name and grade (join code if required). | D38: Child added; no separate login.
A39: PE4 | B39: As a parent with several kids, I want to switch child. | C39: Use the child picker. | D39: Selected child's context is used.
A40: PE5 | B40: As a parent, I want to sign my child up. | C40: Find Opportunities → pick child → open event → sign up. | D40: Child registered; appears on dashboard with calendar.
A41: PE6 | B41: As a parent, child sign-up respects grade/org limits. | C41: Try an ineligible event. | D41: Hidden or blocked with a message.
A42: PE7 | B42: As a parent, I want to see my child's schedule. | C42: Open the dashboard. | D42: Child's upcoming events with add-to-calendar; new sign-ups flagged.
A43: PE8 | B43: As a parent, I want to invite a co-guardian. | C43: Invite a co-guardian by email. | D43: Invite email sent; on registering with that email they share access.
A44: PE9 | B44: As a parent, I want notice when my child signs up. | C44: Sign a child up (or have the other guardian do it). | D44: A notification/confirmation is produced.
A45: PE10 | B45: As a parent, I want to submit my child's hours after an event (child has no login). | C45: Dashboard → the child's 'Submit hours (past events)' → enter hours → Submit. | D45: Hours go to the supervisor for approval; status shows 'Waiting for review'.
A46: PE11 | B46: As a parent, I want to resubmit my child's rejected hours. | C46: On a rejected past event, enter corrected hours → Resubmit. | D46: Returns to 'Waiting for review'.
A47: PE12 | B47: As a parent, I want to see each past event's hours status for my child. | C47: Look at the child's past events list. | D47: Each shows Approved / Waiting / Rejected as appropriate.
... A50: PE15 | B50: As a parent, I want my child's verified service record. | C50: Child card → 'Service record'. | D50: The child's itemized record opens; Print / Save-as-PDF works.
A51: Parent — viewer (grades 6–12 student)
A52: PV1 | B52: As a parent of a 6–12 student, I want to register for view-only access. | C52: Create account → parent of a 6–12 student. | D52: Account created; no invite required to register.
A53: PV2 | B53: As a viewer parent, my student links automatically by email. | C53: Have a student enter this exact email as their parent email (before or after you register). | D53: The student appears on your dashboard automatically; empty until then.
...

Sheet Android
A1: Test cases — Android
A2: ID | B2: User story | C2: Steps to perform | D2: Expected behavior (what you should see) | E2: Result | F2: Comments | G2: Tester
A3: Account & access (all roles)
A4: AC1 | B4: As any user, I want to log in with email and password. | C4: Enter valid email/password and Sign in. | D4: You're signed in and taken to your role's home.
A5: AC2 | B5: As any user, I want to reveal my password while typing. | C5: Tap the eye icon in the password field. | D5: Password text toggles visible/hidden.
A6: AC3 | B6: As any user, I want to reset a forgotten password by email. | C6: Forgot password → enter email → open email → follow link → set new password → sign in. | D6: Reset email arrives; link works; new password signs in; old one fails.
A7: AC4 | B7: As any user, I want to sign out. | C7: Use Sign out. | D7: Logged out; returned to login/landing.
A8: AC5 | B8: As any user, I want a clear error for bad credentials. | C8: Enter a wrong password. | D8: Clear 'login failed' message; stay on login.
A9: AC6 | B9: As any user, my session persists and protected pages are guarded. | C9: Sign in, refresh; then sign out and open a protected URL directly. | D9: Refresh stays signed in; protected pages redirect to login when signed out.
A10: Participant (grades 6–12)
A11: PT1 | B11: As a student (6–12), I want to self-register with the form. | C11: Create account → student option; fill name, email, password, grade, school, parent email; submit. | D11: Account created; signed in on the participant dashboard.
A12: PT2 | B12: As a student, I want to enter an organization code during sign-up. | C12: Enter a code in the Organization code field (optional) and submit. | D12: A valid code enrolls me in that org; a bad code is rejected; blank is allowed.
A13: PT3 | B13: As a participant, I want the correct 7 left-menu tabs. | C13: Look at the left menu. | D13: Exactly: Dashboard, Sign Up, Submit My Hours, Leaderboard, My Reports, My Profile, Help.
A14: PT4 | B14: As a participant, I want a dashboard of my hours and next medal. | C14: Open the dashboard. | D14: Approved-hours ring, next medal + hours to go, and quick actions.
A15: PT5 | B15: As a participant, I want to find and sign up for an opportunity. | C15: Sign Up → Upcoming events → open one → Sign Up. | D15: Registered; confirmation; it moves to My sign-ups.
A16: PT6 | B16: As a participant, I want to add a signed-up event to my calendar. | C16: My sign-ups → add to calendar. | D16: An .ics downloads with correct title/date/time/location.
A17: PT7 | B17: As a participant, I want to see my past events. | C17: Sign Up → Past tab. | D17: Past events are listed.
A18: PT8 | B18: As a participant, I want to search opportunities. | C18: Use the search box (name/description/location). | D18: List filters to matches.
A19: PT9 | B19: As a participant, I want to withdraw from an event. | C19: My sign-ups → red Withdraw → confirm. | D19: Removed; can re-sign up later if space.
A20: PT10 | B20: As a participant, I can only join grade-appropriate events. | C20: Try an event outside your grade range. | D20: Not available / blocked with a grade message.
A21: PT11 | B21: As a participant, I only see my org's or open events. | C21: Browse opportunities. | D21: Open-to-all show; other orgs' private events don't appear.
A22: PT12 | B22: As a participant, I want to check in on event day. | C22: On the day, within the window, use the Check-In panel. | D22: Check-in succeeds; before the window shows 'Not open yet'.
... A34: PT24 | B34: As a participant, I want the recycling ribbon on every page. | C34: Navigate around signed in. | D34: Green ribbon with cans + 100,000 countdown on every page.
A35: Parent — elementary (grades 2–5 child)
A36: PE1 | B36: As a parent, I want to register to manage my grade 2–5 child. | C36: Create account → parent of a 2–5 child. | D36: Parent account created.
A37: PE2 | B37: As an elementary parent, I want the right menu tabs. | C37: Look at the left menu. | D37: Dashboard and Find Opportunities (Help in footer).
A38: PE3 | B38: As a parent, I want to add a managed child (2–5). | C38: Add child with name and grade (join code if required). | D38: Child added; no separate login.
A39: PE4 | B39: As a parent with several kids, I want to switch child. | C39: Use the child picker. | D39: Selected child's context is used.
A40: PE5 | B40: As a parent, I want to sign my child up. | C40: Find Opportunities → pick child → open event → sign up. | D40: Child registered; appears on dashboard with calendar.
A41: PE6 | B41: As a parent, child sign-up respects grade/org limits. | C41: Try an ineligible event. | D41: Hidden or blocked with a message.
A42: PE7 | B42: As a parent, I want to see my child's schedule. | C42: Open the dashboard. | D42: Child's upcoming events with add-to-calendar; new sign-ups flagged.
A43: PE8 | B43: As a parent, I want to invite a co-guardian. | C43: Invite a co-guardian by email. | D43: Invite email sent; on registering with that email they share access.
A44: PE9 | B44: As a parent, I want notice when my child signs up. | C44: Sign a child up (or have the other guardian do it). | D44: A notification/confirmation is produced.
A45: PE10 | B45: As a parent, I want to submit my child's hours after an event (child has no login). | C45: Dashboard → the child's 'Submit hours (past events)' → enter hours → Submit. | D45: Hours go to the supervisor for approval; status shows 'Waiting for review'.
A46: PE11 | B46: As a parent, I want to resubmit my child's rejected hours. | C46: On a rejected past event, enter corrected hours → Resubmit. | D46: Returns to 'Waiting for review'.
A47: PE12 | B47: As a parent, I want to see each past event's hours status for my child. | C47: Look at the child's past events list. | D47: Each shows Approved / Waiting / Rejected as appropriate.
... A50: PE15 | B50: As a parent, I want my child's verified service record. | C50: Child card → 'Service record'. | D50: The child's itemized record opens; Print / Save-as-PDF works.
A51: Parent — viewer (grades 6–12 student)
A52: PV1 | B52: As a parent of a 6–12 student, I want to register for view-only access. | C52: Create account → parent of a 6–12 student. | D52: Account created; no invite required to register.
A53: PV2 | B53: As a viewer parent, my student links automatically by email. | C53: Have a student enter this exact email as their parent email (before or after you register). | D53: The student appears on your dashboard automatically; empty until then.
...

Sheet Desktop Chrome
A1: Test cases — Desktop Chrome
A2: ID | B2: User story | C2: Steps to perform | D2: Expected behavior (what you should see) | E2: Result | F2: Comments | G2: Tester
A3: Account & access (all roles)
A4: AC1 | B4: As any user, I want to log in with email and password. | C4: Enter valid email/password and Sign in. | D4: You're signed in and taken to your role's home.
A5: AC2 | B5: As any user, I want to reveal my password while typing. | C5: Tap the eye icon in the password field. | D5: Password text toggles visible/hidden.
A6: AC3 | B6: As any user, I want to reset a forgotten password by email. | C6: Forgot password → enter email → open email → follow link → set new password → sign in. | D6: Reset email arrives; link works; new password signs in; old one fails.
A7: AC4 | B7: As any user, I want to sign out. | C7: Use Sign out. | D7: Logged out; returned to login/landing.
A8: AC5 | B8: As any user, I want a clear error for bad credentials. | C8: Enter a wrong password. | D8: Clear 'login failed' message; stay on login.
A9: AC6 | B9: As any user, my session persists and protected pages are guarded. | C9: Sign in, refresh; then sign out and open a protected URL directly. | D9: Refresh stays signed in; protected pages redirect to login when signed out.
A10: Participant (grades 6–12)
A11: PT1 | B11: As a student (6–12), I want to self-register with the form. | C11: Create account → student option; fill name, email, password, grade, school, parent email; submit. | D11: Account created; signed in on the participant dashboard.
A12: PT2 | B12: As a student, I want to enter an organization code during sign-up. | C12: Enter a code in the Organization code field (optional) and submit. | D12: A valid code enrolls me in that org; a bad code is rejected; blank is allowed.
A13: PT3 | B13: As a participant, I want the correct 7 left-menu tabs. | C13: Look at the left menu. | D13: Exactly: Dashboard, Sign Up, Submit My Hours, Leaderboard, My Reports, My Profile, Help.
A14: PT4 | B14: As a participant, I want a dashboard of my hours and next medal. | C14: Open the dashboard. | D14: Approved-hours ring, next medal + hours to go, and quick actions.
A15: PT5 | B15: As a participant, I want to find and sign up for an opportunity. | C15: Sign Up → Upcoming events → open one → Sign Up. | D15: Registered; confirmation; it moves to My sign-ups.
A16: PT6 | B16: As a participant, I want to add a signed-up event to my calendar. | C16: My sign-ups → add to calendar. | D16: An .ics downloads with correct title/date/time/location.
A17: PT7 | B17: As a participant, I want to see my past events. | C17: Sign Up → Past tab. | D17: Past events are listed.
A18: PT8 | B18: As a participant, I want to search opportunities. | C18: Use the search box (name/description/location). | D18: List filters to matches.
A19: PT9 | B19: As a participant, I want to withdraw from an event. | C19: My sign-ups → red Withdraw → confirm. | D19: Removed; can re-sign up later if space.
A20: PT10 | B20: As a participant, I can only join grade-appropriate events. | C20: Try an event outside your grade range. | D20: Not available / blocked with a grade message.
A21: PT11 | B21: As a participant, I only see my org's or open events. | C21: Browse opportunities. | D21: Open-to-all show; other orgs' private events don't appear.
A22: PT12 | B22: As a participant, I want to check in on event day. | C22: On the day, within the window, use the Check-In panel. | D22: Check-in succeeds; before the window shows 'Not open yet'.
... A34: PT24 | B34: As a participant, I want the recycling ribbon on every page. | C34: Navigate around signed in. | D34: Green ribbon with cans + 100,000 countdown on every page.
A35: Parent — elementary (grades 2–5 child)
A36: PE1 | B36: As a parent, I want to register to manage my grade 2–5 child. | C36: Create account → parent of a 2–5 child. | D36: Parent account created.
A37: PE2 | B37: As an elementary parent, I want the right menu tabs. | C37: Look at the left menu. | D37: Dashboard and Find Opportunities (Help in footer).
A38: PE3 | B38: As a parent, I want to add a managed child (2–5). | C38: Add child with name and grade (join code if required). | D38: Child added; no separate login.
A39: PE4 | B39: As a parent with several kids, I want to switch child. | C39: Use the child picker. | D39: Selected child's context is used.
A40: PE5 | B40: As a parent, I want to sign my child up. | C40: Find Opportunities → pick child → open event → sign up. | D40: Child registered; appears on dashboard with calendar.
A41: PE6 | B41: As a parent, child sign-up respects grade/org limits. | C41: Try an ineligible event. | D41: Hidden or blocked with a message.
A42: PE7 | B42: As a parent, I want to see my child's schedule. | C42: Open the dashboard. | D42: Child's upcoming events with add-to-calendar; new sign-ups flagged.
A43: PE8 | B43: As a parent, I want to invite a co-guardian. | C43: Invite a co-guardian by email. | D43: Invite email sent; on registering with that email they share access.
A44: PE9 | B44: As a parent, I want notice when my child signs up. | C44: Sign a child up (or have the other guardian do it). | D44: A notification/confirmation is produced.
A45: PE10 | B45: As a parent, I want to submit my child's hours after an event (child has no login). | C45: Dashboard → the child's 'Submit hours (past events)' → enter hours → Submit. | D45: Hours go to the supervisor for approval; status shows 'Waiting for review'.
A46: PE11 | B46: As a parent, I want to resubmit my child's rejected hours. | C46: On a rejected past event, enter corrected hours → Resubmit. | D46: Returns to 'Waiting for review'.
A47: PE12 | B47: As a parent, I want to see each past event's hours status for my child. | C47: Look at the child's past events list. | D47: Each shows Approved / Waiting / Rejected as appropriate.
... A50: PE15 | B50: As a parent, I want my child's verified service record. | C50: Child card → 'Service record'. | D50: The child's itemized record opens; Print / Save-as-PDF works.
A51: Parent — viewer (grades 6–12 student)
A52: PV1 | B52: As a parent of a 6–12 student, I want to register for view-only access. | C52: Create account → parent of a 6–12 student. | D52: Account created; no invite required to register.
A53: PV2 | B53: As a viewer parent, my student links automatically by email. | C53: Have a student enter this exact email as their parent email (before or after you register). | D53: The student appears on your dashboard automatically; empty until then.
...

Sheet Desktop Firefox
A1: Test cases — Desktop Firefox
A2: ID | B2: User story | C2: Steps to perform | D2: Expected behavior (what you should see) | E2: Result | F2: Comments | G2: Tester
A3: Account & access (all roles)
A4: AC1 | B4: As any user, I want to log in with email and password. | C4: Enter valid email/password and Sign in. | D4: You're signed in and taken to your role's home.
A5: AC2 | B5: As any user, I want to reveal my password while typing. | C5: Tap the eye icon in the password field. | D5: Password text toggles visible/hidden.
A6: AC3 | B6: As any user, I want to reset a forgotten password by email. | C6: Forgot password → enter email → open email → follow link → set new password → sign in. | D6: Reset email arrives; link works; new password signs in; old one fails.
A7: AC4 | B7: As any user, I want to sign out. | C7: Use Sign out. | D7: Logged out; returned to login/landing.
A8: AC5 | B8: As any user, I want a clear error for bad credentials. | C8: Enter a wrong password. | D8: Clear 'login failed' message; stay on login.
A9: AC6 | B9: As any user, my session persists and protected pages are guarded. | C9: Sign in, refresh; then sign out and open a protected URL directly. | D9: Refresh stays signed in; protected pages redirect to login when signed out.
A10: Participant (grades 6–12)
A11: PT1 | B11: As a student (6–12), I want to self-register with the form. | C11: Create account → student option; fill name, email, password, grade, school, parent email; submit. | D11: Account created; signed in on the participant dashboard.
A12: PT2 | B12: As a student, I want to enter an organization code during sign-up. | C12: Enter a code in the Organization code field (optional) and submit. | D12: A valid code enrolls me in that org; a bad code is rejected; blank is allowed.
A13: PT3 | B13: As a participant, I want the correct 7 left-menu tabs. | C13: Look at the left menu. | D13: Exactly: Dashboard, Sign Up, Submit My Hours, Leaderboard, My Reports, My Profile, Help.
A14: PT4 | B14: As a participant, I want a dashboard of my hours and next medal. | C14: Open the dashboard. | D14: Approved-hours ring, next medal + hours to go, and quick actions.
A15: PT5 | B15: As a participant, I want to find and sign up for an opportunity. | C15: Sign Up → Upcoming events → open one → Sign Up. | D15: Registered; confirmation; it moves to My sign-ups.
A16: PT6 | B16: As a participant, I want to add a signed-up event to my calendar. | C16: My sign-ups → add to calendar. | D16: An .ics downloads with correct title/date/time/location.
A17: PT7 | B17: As a participant, I want to see my past events. | C17: Sign Up → Past tab. | D17: Past events are listed.
A18: PT8 | B18: As a participant, I want to search opportunities. | C18: Use the search box (name/description/location). | D18: List filters to matches.
A19: PT9 | B19: As a participant, I want to withdraw from an event. | C19: My sign-ups → red Withdraw → confirm. | D19: Removed; can re-sign up later if space.
A20: PT10 | B20: As a participant, I can only join grade-appropriate events. | C20: Try an event outside your grade range. | D20: Not available / blocked with a grade message.
A21: PT11 | B21: As a participant, I only see my org's or open events. | C21: Browse opportunities. | D21: Open-to-all show; other orgs' private events don't appear.
A22: PT12 | B22: As a participant, I want to check in on event day. | C22: On the day, within the window, use the Check-In panel. | D22: Check-in succeeds; before the window shows 'Not open yet'.
... A34: PT24 | B34: As a participant, I want the recycling ribbon on every page. | C34: Navigate around signed in. | D34: Green ribbon with cans + 100,000 countdown on every page.
A35: Parent — elementary (grades 2–5 child)
A36: PE1 | B36: As a parent, I want to register to manage my grade 2–5 child. | C36: Create account → parent of a 2–5 child. | D36: Parent account created.
A37: PE2 | B37: As an elementary parent, I want the right menu tabs. | C37: Look at the left menu. | D37: Dashboard and Find Opportunities (Help in footer).
A38: PE3 | B38: As a parent, I want to add a managed child (2–5). | C38: Add child with name and grade (join code if required). | D38: Child added; no separate login.
A39: PE4 | B39: As a parent with several kids, I want to switch child. | C39: Use the child picker. | D39: Selected child's context is used.
A40: PE5 | B40: As a parent, I want to sign my child up. | C40: Find Opportunities → pick child → open event → sign up. | D40: Child registered; appears on dashboard with calendar.
A41: PE6 | B41: As a parent, child sign-up respects grade/org limits. | C41: Try an ineligible event. | D41: Hidden or blocked with a message.
A42: PE7 | B42: As a parent, I want to see my child's schedule. | C42: Open the dashboard. | D42: Child's upcoming events with add-to-calendar; new sign-ups flagged.
A43: PE8 | B43: As a parent, I want to invite a co-guardian. | C43: Invite a co-guardian by email. | D43: Invite email sent; on registering with that email they share access.
A44: PE9 | B44: As a parent, I want notice when my child signs up. | C44: Sign a child up (or have the other guardian do it). | D44: A notification/confirmation is produced.
A45: PE10 | B45: As a parent, I want to submit my child's hours after an event (child has no login). | C45: Dashboard → the child's 'Submit hours (past events)' → enter hours → Submit. | D45: Hours go to the supervisor for approval; status shows 'Waiting for review'.
A46: PE11 | B46: As a parent, I want to resubmit my child's rejected hours. | C46: On a rejected past event, enter corrected hours → Resubmit. | D46: Returns to 'Waiting for review'.
A47: PE12 | B47: As a parent, I want to see each past event's hours status for my child. | C47: Look at the child's past events list. | D47: Each shows Approved / Waiting / Rejected as appropriate.
... A50: PE15 | B50: As a parent, I want my child's verified service record. | C50: Child card → 'Service record'. | D50: The child's itemized record opens; Print / Save-as-PDF works.
A51: Parent — viewer (grades 6–12 student)
A52: PV1 | B52: As a parent of a 6–12 student, I want to register for view-only access. | C52: Create account → parent of a 6–12 student. | D52: Account created; no invite required to register.
A53: PV2 | B53: As a viewer parent, my student links automatically by email. | C53: Have a student enter this exact email as their parent email (before or after you register). | D53: The student appears on your dashboard automatically; empty until then.
...

Sheet Desktop Other
A1: Test cases — Desktop Other
A2: ID | B2: User story | C2: Steps to perform | D2: Expected behavior (what you should see) | E2: Result | F2: Comments | G2: Tester
A3: Account & access (all roles)
A4: AC1 | B4: As any user, I want to log in with email and password. | C4: Enter valid email/password and Sign in. | D4: You're signed in and taken to your role's home.
A5: AC2 | B5: As any user, I want to reveal my password while typing. | C5: Tap the eye icon in the password field. | D5: Password text toggles visible/hidden.
A6: AC3 | B6: As any user, I want to reset a forgotten password by email. | C6: Forgot password → enter email → open email → follow link → set new password → sign in. | D6: Reset email arrives; link works; new password signs in; old one fails.
A7: AC4 | B7: As any user, I want to sign out. | C7: Use Sign out. | D7: Logged out; returned to login/landing.
A8: AC5 | B8: As any user, I want a clear error for bad credentials. | C8: Enter a wrong password. | D8: Clear 'login failed' message; stay on login.
A9: AC6 | B9: As any user, my session persists and protected pages are guarded. | C9: Sign in, refresh; then sign out and open a protected URL directly. | D9: Refresh stays signed in; protected pages redirect to login when signed out.
A10: Participant (grades 6–12)
A11: PT1 | B11: As a student (6–12), I want to self-register with the form. | C11: Create account → student option; fill name, email, password, grade, school, parent email; submit. | D11: Account created; signed in on the participant dashboard.
A12: PT2 | B12: As a student, I want to enter an organization code during sign-up. | C12: Enter a code in the Organization code field (optional) and submit. | D12: A valid code enrolls me in that org; a bad code is rejected; blank is allowed.
A13: PT3 | B13: As a participant, I want the correct 7 left-menu tabs. | C13: Look at the left menu. | D13: Exactly: Dashboard, Sign Up, Submit My Hours, Leaderboard, My Reports, My Profile, Help.
A14: PT4 | B14: As a participant, I want a dashboard of my hours and next medal. | C14: Open the dashboard. | D14: Approved-hours ring, next medal + hours to go, and quick actions.
A15: PT5 | B15: As a participant, I want to find and sign up for an opportunity. | C15: Sign Up → Upcoming events → open one → Sign Up. | D15: Registered; confirmation; it moves to My sign-ups.
A16: PT6 | B16: As a participant, I want to add a signed-up event to my calendar. | C16: My sign-ups → add to calendar. | D16: An .ics downloads with correct title/date/time/location.
A17: PT7 | B17: As a participant, I want to see my past events. | C17: Sign Up → Past tab. | D17: Past events are listed.
A18: PT8 | B18: As a participant, I want to search opportunities. | C18: Use the search box (name/description/location). | D18: List filters to matches.
A19: PT9 | B19: As a participant, I want to withdraw from an event. | C19: My sign-ups → red Withdraw → confirm. | D19: Removed; can re-sign up later if space.
A20: PT10 | B20: As a participant, I can only join grade-appropriate events. | C20: Try an event outside your grade range. | D20: Not available / blocked with a grade message.
A21: PT11 | B21: As a participant, I only see my org's or open events. | C21: Browse opportunities. | D21: Open-to-all show; other orgs' private events don't appear.
A22: PT12 | B22: As a participant, I want to check in on event day. | C22: On the day, within the window, use the Check-In panel. | D22: Check-in succeeds; before the window shows 'Not open yet'.
... A34: PT24 | B34: As a participant, I want the recycling ribbon on every page. | C34: Navigate around signed in. | D34: Green ribbon with cans + 100,000 countdown on every page.
A35: Parent — elementary (grades 2–5 child)
A36: PE1 | B36: As a parent, I want to register to manage my grade 2–5 child. | C36: Create account → parent of a 2–5 child. | D36: Parent account created.
A37: PE2 | B37: As an elementary parent, I want the right menu tabs. | C37: Look at the left menu. | D37: Dashboard and Find Opportunities (Help in footer).
A38: PE3 | B38: As a parent, I want to add a managed child (2–5). | C38: Add child with name and grade (join code if required). | D38: Child added; no separate login.
A39: PE4 | B39: As a parent with several kids, I want to switch child. | C39: Use the child picker. | D39: Selected child's context is used.
A40: PE5 | B40: As a parent, I want to sign my child up. | C40: Find Opportunities → pick child → open event → sign up. | D40: Child registered; appears on dashboard with calendar.
A41: PE6 | B41: As a parent, child sign-up respects grade/org limits. | C41: Try an ineligible event. | D41: Hidden or blocked with a message.
A42: PE7 | B42: As a parent, I want to see my child's schedule. | C42: Open the dashboard. | D42: Child's upcoming events with add-to-calendar; new sign-ups flagged.
A43: PE8 | B43: As a parent, I want to invite a co-guardian. | C43: Invite a co-guardian by email. | D43: Invite email sent; on registering with that email they share access.
A44: PE9 | B44: As a parent, I want notice when my child signs up. | C44: Sign a child up (or have the other guardian do it). | D44: A notification/confirmation is produced.
A45: PE10 | B45: As a parent, I want to submit my child's hours after an event (child has no login). | C45: Dashboard → the child's 'Submit hours (past events)' → enter hours → Submit. | D45: Hours go to the supervisor for approval; status shows 'Waiting for review'.
A46: PE11 | B46: As a parent, I want to resubmit my child's rejected hours. | C46: On a rejected past event, enter corrected hours → Resubmit. | D46: Returns to 'Waiting for review'.
A47: PE12 | B47: As a parent, I want to see each past event's hours status for my child. | C47: Look at the child's past events list. | D47: Each shows Approved / Waiting / Rejected as appropriate.
... A50: PE15 | B50: As a parent, I want my child's verified service record. | C50: Child card → 'Service record'. | D50: The child's itemized record opens; Print / Save-as-PDF works.
A51: Parent — viewer (grades 6–12 student)
A52: PV1 | B52: As a parent of a 6–12 student, I want to register for view-only access. | C52: Create account → parent of a 6–12 student. | D52: Account created; no invite required to register.
A53: PV2 | B53: As a viewer parent, my student links automatically by email. | C53: Have a student enter this exact email as their parent email (before or after you register). | D53: The student appears on your dashboard automatically; empty until then.
...
